Workbook

Sheet Hodnocení
A1: Hodnocení ukázek článků (naslepo)
A2: Hodnotitel/ka:
A3: Hodnotím za:
A4: Stupnice 1–5: 5 = vydat po drobné úpravě, 4 = do 15 minut úprav, 3 = větší úpravy, 2 = přepsat podstatnou část, 1 = nepoužitelné. Povinné je jen Celkově. Řádky verzí, které neprošly kontrolou (šedé), nevyplňujte. Návod je na listu Návod.
A6: Označení | B6: Téma | C6: Název tématu | D6: Cesta | E6: Stav verze | F6: K hodnocení | G6: Celkově (1–5) | H6: Úhel a zpracování (1–5) | I6: Fakta (1–5) | J6: Styl a tón (1–5) | K6: Struktura (1–5) | L6: Odkazy a zdroje (1–5) | M6: Poznámka | N6: Kontrola
A7: T1-A | B7: T1 | C7: OECD: podíl vysokoškoláků v Česku | D7: Rozšířená rešerše | E7: neprošla – nehodnotí se | F7: ne | N7: =IF(COUNTA(G7:L7)>0,"neprošlá verze se nehodnotí","")
A8: T1-B | B8: T1 | C8: OECD: podíl vysokoškoláků v Česku | D8: Rozšířená rešerše | E8: prošla po jedné opravě | F8: ano | N8: =IF(COUNTA(G8:L8)<>COUNTIF(G8:L8,1)+COUNTIF(G8:L8,2)+COUNTIF(G8:L8,3)+COUNTIF(G8:L8,4)+COUNTIF(G8:L8,5),"jen celá čísla 1–5",IF(AND(COUNTA(H8:L8)>0,COUNTA(G8)=0),"doplňte Celkově",""))
A9: T1-C | B9: T1 | C9: OECD: podíl vysokoškoláků v Česku | D9: Rozšířená rešerše | E9: prošla po jedné opravě | F9: ano | N9: =IF(COUNTA(G9:L9)<>COUNTIF(G9:L9,1)+COUNTIF(G9:L9,2)+COUNTIF(G9:L9,3)+COUNTIF(G9:L9,4)+COUNTIF(G9:L9,5),"jen celá čísla 1–5",IF(AND(COUNTA(H9:L9)>0,COUNTA(G9)=0),"doplňte Celkově",""))
A10: T1-D | B10: T1 | C10: OECD: podíl vysokoškoláků v Česku | D10: Rozšířená rešerše | E10: prošla po jedné opravě | F10: ano | N10: =IF(COUNTA(G10:L10)<>COUNTIF(G10:L10,1)+COUNTIF(G10:L10,2)+COUNTIF(G10:L10,3)+COUNTIF(G10:L10,4)+COUNTIF(G10:L10,5),"jen celá čísla 1–5",IF(AND(COUNTA(H10:L10)>0,COUNTA(G10)=0),"doplňte Celkově",""))
A11: T1-E | B11: T1 | C11: OECD: podíl vysokoškoláků v Česku | D11: Rozšířená rešerše | E11: prošla po jedné opravě | F11: ano | N11: =IF(COUNTA(G11:L11)<>COUNTIF(G11:L11,1)+COUNTIF(G11:L11,2)+COUNTIF(G11:L11,3)+COUNTIF(G11:L11,4)+COUNTIF(G11:L11,5),"jen celá čísla 1–5",IF(AND(COUNTA(H11:L11)>0,COUNTA(G11)=0),"doplňte Celkově",""))
A12: T1-auto-A | B12: T1 | C12: OECD: podíl vysokoškoláků v Česku | D12: Automatická cesta | E12: prošla po jedné opravě | F12: ano | N12: =IF(COUNTA(G12:L12)<>COUNTIF(G12:L12,1)+COUNTIF(G12:L12,2)+COUNTIF(G12:L12,3)+COUNTIF(G12:L12,4)+COUNTIF(G12:L12,5),"jen celá čísla 1–5",IF(AND(COUNTA(H12:L12)>0,COUNTA(G12)=0),"doplňte Celkově",""))
A13: T1-auto-B | B13: T1 | C13: OECD: podíl vysokoškoláků v Česku | D13: Automatická cesta | E13: neprošla – nehodnotí se | F13: ne | N13: =IF(COUNTA(G13:L13)>0,"neprošlá verze se nehodnotí","")
A14: T1-auto-C | B14: T1 | C14: OECD: podíl vysokoškoláků v Česku | D14: Automatická cesta | E14: neprošla – nehodnotí se | F14: ne | N14: =IF(COUNTA(G14:L14)>0,"neprošlá verze se nehodnotí","")
A15: T1-auto-D | B15: T1 | C15: OECD: podíl vysokoškoláků v Česku | D15: Automatická cesta | E15: prošla po jedné opravě | F15: ano | N15: =IF(COUNTA(G15:L15)<>COUNTIF(G15:L15,1)+COUNTIF(G15:L15,2)+COUNTIF(G15:L15,3)+COUNTIF(G15:L15,4)+COUNTIF(G15:L15,5),"jen celá čísla 1–5",IF(AND(COUNTA(H15:L15)>0,COUNTA(G15)=0),"doplňte Celkově",""))
A16: T1-auto-E | B16: T1 | C16: OECD: podíl vysokoškoláků v Česku | D16: Automatická cesta | E16: prošla po jedné opravě | F16: ano | N16: =IF(COUNTA(G16:L16)<>COUNTIF(G16:L16,1)+COUNTIF(G16:L16,2)+COUNTIF(G16:L16,3)+COUNTIF(G16:L16,4)+COUNTIF(G16:L16,5),"jen celá čísla 1–5",IF(AND(COUNTA(H16:L16)>0,COUNTA(G16)=0),"doplňte Celkově",""))
A17: T2-A | B17: T2 | C17: Nový kampus UK v Hradci Králové | D17: Rozšířená rešerše | E17: prošla napoprvé | F17: ano | N17: =IF(COUNTA(G17:L17)<>COUNTIF(G17:L17,1)+COUNTIF(G17:L17,2)+COUNTIF(G17:L17,3)+COUNTIF(G17:L17,4)+COUNTIF(G17:L17,5),"jen celá čísla 1–5",IF(AND(COUNTA(H17:L17)>0,COUNTA(G17)=0),"doplňte Celkově",""))
A18: T2-B | B18: T2 | C18: Nový kampus UK v Hradci Králové | D18: Rozšířená rešerše | E18: neprošla – nehodnotí se | F18: ne | N18: =IF(COUNTA(G18:L18)>0,"neprošlá verze se nehodnotí","")
A19: T2-C | B19: T2 | C19: Nový kampus UK v Hradci Králové | D19: Rozšířená rešerše | E19: prošla napoprvé | F19: ano | N19: =IF(COUNTA(G19:L19)<>COUNTIF(G19:L19,1)+COUNTIF(G19:L19,2)+COUNTIF(G19:L19,3)+COUNTIF(G19:L19,4)+COUNTIF(G19:L19,5),"jen celá čísla 1–5",IF(AND(COUNTA(H19:L19)>0,COUNTA(G19)=0),"doplňte Celkově",""))
A20: T2-D | B20: T2 | C20: Nový kampus UK v Hradci Králové | D20: Rozšířená rešerše | E20: prošla napoprvé | F20: ano | N20: =IF(COUNTA(G20:L20)<>COUNTIF(G20:L20,1)+COUNTIF(G20:L20,2)+COUNTIF(G20:L20,3)+COUNTIF(G20:L20,4)+COUNTIF(G20:L20,5),"jen celá čísla 1–5",IF(AND(COUNTA(H20:L20)>0,COUNTA(G20)=0),"doplňte Celkově",""))
A21: T2-E | B21: T2 | C21: Nový kampus UK v Hradci Králové | D21: Rozšířená rešerše | E21: prošla po jedné opravě | F21: ano | N21: =IF(COUNTA(G21:L21)<>COUNTIF(G21:L21,1)+COUNTIF(G21:L21,2)+COUNTIF(G21:L21,3)+COUNTIF(G21:L21,4)+COUNTIF(G21:L21,5),"jen celá čísla 1–5",IF(AND(COUNTA(H21:L21)>0,COUNTA(G21)=0),"doplňte Celkově",""))
A22: T3-A | B22: T3 | C22: Přestavba strahovských kolejí ČVUT | D22: Rozšířená rešerše | E22: prošla po jedné opravě | F22: ano | N22: =IF(COUNTA(G22:L22)<>COUNTIF(G22:L22,1)+COUNTIF(G22:L22,2)+COUNTIF(G22:L22,3)+COUNTIF(G22:L22,4)+COUNTIF(G22:L22,5),"jen celá čísla 1–5",IF(AND(COUNTA(H22:L22)>0,COUNTA(G22)=0),"doplňte Celkově",""))
A23: T3-B | B23: T3 | C23: Přestavba strahovských kolejí ČVUT | D23: Rozšířená rešerše | E23: prošla po jedné opravě | F23: ano | N23: =IF(COUNTA(G23:L23)<>COUNTIF(G23:L23,1)+COUNTIF(G23:L23,2)+COUNTIF(G23:L23,3)+COUNTIF(G23:L23,4)+COUNTIF(G23:L23,5),"jen celá čísla 1–5",IF(AND(COUNTA(H23:L23)>0,COUNTA(G23)=0),"doplňte Celkově",""))
A24: T3-C | B24: T3 | C24: Přestavba strahovských kolejí ČVUT | D24: Rozšířená rešerše | E24: prošla po jedné opravě | F24: ano | N24: =IF(COUNTA(G24:L24)<>COUNTIF(G24:L24,1)+COUNTIF(G24:L24,2)+COUNTIF(G24:L24,3)+COUNTIF(G24:L24,4)+COUNTIF(G24:L24,5),"jen celá čísla 1–5",IF(AND(COUNTA(H24:L24)>0,COUNTA(G24)=0),"doplňte Celkově",""))
A25: T3-D | B25: T3 | C25: Přestavba strahovských kolejí ČVUT | D25: Rozšířená rešerše | E25: neprošla – nehodnotí se | F25: ne | N25: =IF(COUNTA(G25:L25)>0,"neprošlá verze se nehodnotí","")
A26: T3-E | B26: T3 | C26: Přestavba strahovských kolejí ČVUT | D26: Rozšířená rešerše | E26: prošla napoprvé | F26: ano | N26: =IF(COUNTA(G26:L26)<>COUNTIF(G26:L26,1)+COUNTIF(G26:L26,2)+COUNTIF(G26:L26,3)+COUNTIF(G26:L26,4)+COUNTIF(G26:L26,5),"jen celá čísla 1–5",IF(AND(COUNTA(H26:L26)>0,COUNTA(G26)=0),"doplňte Celkově",""))
A27: T14-A | B27: T14 | C27: Scio chce založit vlastní vysokou školu | D27: Rozšířená rešerše | E27: neprošla – nehodnotí se | F27: ne | N27: =IF(COUNTA(G27:L27)>0,"neprošlá verze se nehodnotí","")
A28: T14-B | B28: T14 | C28: Scio chce založit vlastní vysokou školu | D28: Rozšířená rešerše | E28: neprošla – nehodnotí se | F28: ne | N28: =IF(COUNTA(G28:L28)>0,"neprošlá verze se nehodnotí","")
A29: T14-C | B29: T14 | C29: Scio chce založit vlastní vysokou školu | D29: Rozšířená rešerše | E29: neprošla – nehodnotí se | F29: ne | N29: =IF(COUNTA(G29:L29)>0,"neprošlá verze se nehodnotí","")
A30: T14-D | B30: T14 | C30: Scio chce založit vlastní vysokou školu | D30: Rozšířená rešerše | E30: prošla po jedné opravě | F30: ano | N30: =IF(COUNTA(G30:L30)<>COUNTIF(G30:L30,1)+COUNTIF(G30:L30,2)+COUNTIF(G30:L30,3)+COUNTIF(G30:L30,4)+COUNTIF(G30:L30,5),"jen celá čísla 1–5",IF(AND(COUNTA(H30:L30)>0,COUNTA(G30)=0),"doplňte Celkově",""))
A31: T14-E | B31: T14 | C31: Scio chce založit vlastní vysokou školu | D31: Rozšířená rešerše | E31: prošla po jedné opravě | F31: ano | N31: =IF(COUNTA(G31:L31)<>COUNTIF(G31:L31,1)+COUNTIF(G31:L31,2)+COUNTIF(G31:L31,3)+COUNTIF(G31:L31,4)+COUNTIF(G31:L31,5),"jen celá čísla 1–5",IF(AND(COUNTA(H31:L31)>0,COUNTA(G31)=0),"doplňte Celkově",""))
A32: T15-auto-A | B32: T15 | C32: Univerzitní hokejová derby | D32: Automatická cesta | E32: neprošla – nehodnotí se | F32: ne | N32: =IF(COUNTA(G32:L32)>0,"neprošlá verze se nehodnotí","")
A33: T15-auto-B | B33: T15 | C33: Univerzitní hokejová derby | D33: Automatická cesta | E33: prošla po jedné opravě | F33: ano | N33: =IF(COUNTA(G33:L33)<>COUNTIF(G33:L33,1)+COUNTIF(G33:L33,2)+COUNTIF(G33:L33,3)+COUNTIF(G33:L33,4)+COUNTIF(G33:L33,5),"jen celá čísla 1–5",IF(AND(COUNTA(H33:L33)>0,COUNTA(G33)=0),"doplňte Celkově",""))
A34: T15-auto-C | B34: T15 | C34: Univerzitní hokejová derby | D34: Automatická cesta | E34: prošla napoprvé | F34: ano | N34: =IF(COUNTA(G34:L34)<>COUNTIF(G34:L34,1)+COUNTIF(G34:L34,2)+COUNTIF(G34:L34,3)+COUNTIF(G34:L34,4)+COUNTIF(G34:L34,5),"jen celá čísla 1–5",IF(AND(COUNTA(H34:L34)>0,COUNTA(G34)=0),"doplňte Celkově",""))
A35: T15-auto-D | B35: T15 | C35: Univerzitní hokejová derby | D35: Automatická cesta | E35: prošla napoprvé | F35: ano | N35: =IF(COUNTA(G35:L35)<>COUNTIF(G35:L35,1)+COUNTIF(G35:L35,2)+COUNTIF(G35:L35,3)+COUNTIF(G35:L35,4)+COUNTIF(G35:L35,5),"jen celá čísla 1–5",IF(AND(COUNTA(H35:L35)>0,COUNTA(G35)=0),"doplňte Celkově",""))
A36: T15-auto-E | B36: T15 | C36: Univerzitní hokejová derby | D36: Automatická cesta | E36: prošla napoprvé | F36: ano | N36: =IF(COUNTA(G36:L36)<>COUNTIF(G36:L36,1)+COUNTIF(G36:L36,2)+COUNTIF(G36:L36,3)+COUNTIF(G36:L36,4)+COUNTIF(G36:L36,5),"jen celá čísla 1–5",IF(AND(COUNTA(H36:L36)>0,COUNTA(G36)=0),"doplňte Celkově",""))
A37: T16-A | B37: T16 | C37: Neúspěch u maturity: jak na další pokus | D37: Rozšířená rešerše | E37: prošla napoprvé | F37: ano | N37: =IF(COUNTA(G37:L37)<>COUNTIF(G37:L37,1)+COUNTIF(G37:L37,2)+COUNTIF(G37:L37,3)+COUNTIF(G37:L37,4)+COUNTIF(G37:L37,5),"jen celá čísla 1–5",IF(AND(COUNTA(H37:L37)>0,COUNTA(G37)=0),"doplňte Celkově",""))
A38: T16-B | B38: T16 | C38: Neúspěch u maturity: jak na další pokus | D38: Rozšířená rešerše | E38: prošla po jedné opravě | F38: ano | N38: =IF(COUNTA(G38:L38)<>COUNTIF(G38:L38,1)+COUNTIF(G38:L38,2)+COUNTIF(G38:L38,3)+COUNTIF(G38:L38,4)+COUNTIF(G38:L38,5),"jen celá čísla 1–5",IF(AND(COUNTA(H38:L38)>0,COUNTA(G38)=0),"doplňte Celkově",""))
A39: T16-C | B39: T16 | C39: Neúspěch u maturity: jak na další pokus | D39: Rozšířená rešerše | E39: prošla po jedné opravě | F39: ano | N39: =IF(COUNTA(G39:L39)<>COUNTIF(G39:L39,1)+COUNTIF(G39:L39,2)+COUNTIF(G39:L39,3)+COUNTIF(G39:L39,4)+COUNTIF(G39:L39,5),"jen celá čísla 1–5",IF(AND(COUNTA(H39:L39)>0,COUNTA(G39)=0),"doplňte Celkově",""))
A40: T16-D | B40: T16 | C40: Neúspěch u maturity: jak na další pokus | D40: Rozšířená rešerše | E40: prošla po jedné opravě | F40: ano | N40: =IF(COUNTA(G40:L40)<>COUNTIF(G40:L40,1)+COUNTIF(G40:L40,2)+COUNTIF(G40:L40,3)+COUNTIF(G40:L40,4)+COUNTIF(G40:L40,5),"jen celá čísla 1–5",IF(AND(COUNTA(H40:L40)>0,COUNTA(G40)=0),"doplňte Celkově",""))
A41: T16-E | B41: T16 | C41: Neúspěch u maturity: jak na další pokus | D41: Rozšířená rešerše | E41: prošla napoprvé | F41: ano | N41: =IF(COUNTA(G41:L41)<>COUNTIF(G41:L41,1)+COUNTIF(G41:L41,2)+COUNTIF(G41:L41,3)+COUNTIF(G41:L41,4)+COUNTIF(G41:L41,5),"jen celá čísla 1–5",IF(AND(COUNTA(H41:L41)>0,COUNTA(G41)=0),"doplňte Celkově",""))
...

Sheet Souhrn
A1: Souhrn vašeho hodnocení (počítá se samo z listu Hodnocení)
A3: Ohodnoceno verzí (Celkově): | B3: =COUNTIFS('Hodnocení'!F7:F46,"ano",'Hodnocení'!G7:G46,">=1",'Hodnocení'!G7:G46,"<=5")
A4: Verzí k hodnocení: | B4: =COUNTIF('Hodnocení'!F7:F46,"ano")
A5: Průměr Celkově: | B5: =IFERROR(AVERAGEIFS('Hodnocení'!G7:G46,'Hodnocení'!F7:F46,"ano",'Hodnocení'!G7:G46,">=1",'Hodnocení'!G7:G46,"<=5"),"")
A7: Téma | B7: Název tématu | C7: Cesta | D7: K hodnocení | E7: Ohodnoceno | F7: Průměr Celkově
A8: T1 | B8: OECD: podíl vysokoškoláků v Česku | C8: Rozšířená rešerše | D8: =COUNTIFS('Hodnocení'!B7:B46,A8,'Hodnocení'!D7:D46,C8,'Hodnocení'!F7:F46,"ano") | E8: =COUNTIFS('Hodnocení'!B7:B46,A8,'Hodnocení'!D7:D46,C8,'Hodnocení'!F7:F46,"ano",'Hodnocení'!G7:G46,">=1",'Hodnocení'!G7:G46,"<=5") | F8: =IFERROR(AVERAGEIFS('Hodnocení'!G7:G46,'Hodnocení'!B7:B46,A8,'Hodnocení'!D7:D46,C8,'Hodnocení'!F7:F46,"ano",'Hodnocení'!G7:G46,">=1",'Hodnocení'!G7:G46,"<=5"),"")
A9: T1 | B9: OECD: podíl vysokoškoláků v Česku | C9: Automatická cesta | D9: =COUNTIFS('Hodnocení'!B7:B46,A9,'Hodnocení'!D7:D46,C9,'Hodnocení'!F7:F46,"ano") | E9: =COUNTIFS('Hodnocení'!B7:B46,A9,'Hodnocení'!D7:D46,C9,'Hodnocení'!F7:F46,"ano",'Hodnocení'!G7:G46,">=1",'Hodnocení'!G7:G46,"<=5") | F9: =IFERROR(AVERAGEIFS('Hodnocení'!G7:G46,'Hodnocení'!B7:B46,A9,'Hodnocení'!D7:D46,C9,'Hodnocení'!F7:F46,"ano",'Hodnocení'!G7:G46,">=1",'Hodnocení'!G7:G46,"<=5"),"")
A10: T2 | B10: Nový kampus UK v Hradci Králové | C10: Rozšířená rešerše | D10: =COUNTIFS('Hodnocení'!B7:B46,A10,'Hodnocení'!D7:D46,C10,'Hodnocení'!F7:F46,"ano") | E10: =COUNTIFS('Hodnocení'!B7:B46,A10,'Hodnocení'!D7:D46,C10,'Hodnocení'!F7:F46,"ano",'Hodnocení'!G7:G46,">=1",'Hodnocení'!G7:G46,"<=5") | F10: =IFERROR(AVERAGEIFS('Hodnocení'!G7:G46,'Hodnocení'!B7:B46,A10,'Hodnocení'!D7:D46,C10,'Hodnocení'!F7:F46,"ano",'Hodnocení'!G7:G46,">=1",'Hodnocení'!G7:G46,"<=5"),"")
A11: T3 | B11: Přestavba strahovských kolejí ČVUT | C11: Rozšířená rešerše | D11: =COUNTIFS('Hodnocení'!B7:B46,A11,'Hodnocení'!D7:D46,C11,'Hodnocení'!F7:F46,"ano") | E11: =COUNTIFS('Hodnocení'!B7:B46,A11,'Hodnocení'!D7:D46,C11,'Hodnocení'!F7:F46,"ano",'Hodnocení'!G7:G46,">=1",'Hodnocení'!G7:G46,"<=5") | F11: =IFERROR(AVERAGEIFS('Hodnocení'!G7:G46,'Hodnocení'!B7:B46,A11,'Hodnocení'!D7:D46,C11,'Hodnocení'!F7:F46,"ano",'Hodnocení'!G7:G46,">=1",'Hodnocení'!G7:G46,"<=5"),"")
A12: T14 | B12: Scio chce založit vlastní vysokou školu | C12: Rozšířená rešerše | D12: =COUNTIFS('Hodnocení'!B7:B46,A12,'Hodnocení'!D7:D46,C12,'Hodnocení'!F7:F46,"ano") | E12: =COUNTIFS('Hodnocení'!B7:B46,A12,'Hodnocení'!D7:D46,C12,'Hodnocení'!F7:F46,"ano",'Hodnocení'!G7:G46,">=1",'Hodnocení'!G7:G46,"<=5") | F12: =IFERROR(AVERAGEIFS('Hodnocení'!G7:G46,'Hodnocení'!B7:B46,A12,'Hodnocení'!D7:D46,C12,'Hodnocení'!F7:F46,"ano",'Hodnocení'!G7:G46,">=1",'Hodnocení'!G7:G46,"<=5"),"")
A13: T15 | B13: Univerzitní hokejová derby | C13: Automatická cesta | D13: =COUNTIFS('Hodnocení'!B7:B46,A13,'Hodnocení'!D7:D46,C13,'Hodnocení'!F7:F46,"ano") | E13: =COUNTIFS('Hodnocení'!B7:B46,A13,'Hodnocení'!D7:D46,C13,'Hodnocení'!F7:F46,"ano",'Hodnocení'!G7:G46,">=1",'Hodnocení'!G7:G46,"<=5") | F13: =IFERROR(AVERAGEIFS('Hodnocení'!G7:G46,'Hodnocení'!B7:B46,A13,'Hodnocení'!D7:D46,C13,'Hodnocení'!F7:F46,"ano",'Hodnocení'!G7:G46,">=1",'Hodnocení'!G7:G46,"<=5"),"")
A14: T16 | B14: Neúspěch u maturity: jak na další pokus | C14: Rozšířená rešerše | D14: =COUNTIFS('Hodnocení'!B7:B46,A14,'Hodnocení'!D7:D46,C14,'Hodnocení'!F7:F46,"ano") | E14: =COUNTIFS('Hodnocení'!B7:B46,A14,'Hodnocení'!D7:D46,C14,'Hodnocení'!F7:F46,"ano",'Hodnocení'!G7:G46,">=1",'Hodnocení'!G7:G46,"<=5") | F14: =IFERROR(AVERAGEIFS('Hodnocení'!G7:G46,'Hodnocení'!B7:B46,A14,'Hodnocení'!D7:D46,C14,'Hodnocení'!F7:F46,"ano",'Hodnocení'!G7:G46,">=1",'Hodnocení'!G7:G46,"<=5"),"")
A15: T17 | B15: Farmaceutická fakulta UK v novém kampusu v Hradci Králové: první týdny | C15: Rozšířená rešerše | D15: =COUNTIFS('Hodnocení'!B7:B46,A15,'Hodnocení'!D7:D46,C15,'Hodnocení'!F7:F46,"ano") | E15: =COUNTIFS('Hodnocení'!B7:B46,A15,'Hodnocení'!D7:D46,C15,'Hodnocení'!F7:F46,"ano",'Hodnocení'!G7:G46,">=1",'Hodnocení'!G7:G46,"<=5") | F15: =IFERROR(AVERAGEIFS('Hodnocení'!G7:G46,'Hodnocení'!B7:B46,A15,'Hodnocení'!D7:D46,C15,'Hodnocení'!F7:F46,"ano",'Hodnocení'!G7:G46,">=1",'Hodnocení'!G7:G46,"<=5"),"")

Sheet Návod
A1: Ukázky článků: hodnocení naslepo
A2: Pět jazykových modelů napsalo stejná témata ze září a začátku října. Prosíme vás, abyste si verze v klidu přečetli a ohodnotili. Hodnocení lidí z VysokeSkoly.cz a z EffiStreamu rozhodne, který model bude články psát. Na schůzce verze projdeme společně.
A4: Jak číst označení verzí
A5: Verze jsou u každého tématu označené písmeny A–E. Písmena jsou u každého tématu vylosovaná zvlášť: verze A u jednoho tématu nemusí být stejný model jako verze A u jiného.
A6: U některých témat jsou dvě cesty ke zdrojům. Stejné písmeno znamená u jednoho tématu v obou cestách stejný model: verze T1-B i T1-auto-B napsal tentýž model.
A7: Každá verze má označení pro hodnocení (třeba T1-A nebo T1-auto-B). Stejné označení najdete v tabulce.
A9: Jak hodnotit
A10: Každé kritérium hodnoťte na stupnici 1–5. Povinné je jen Celkově; dílčí kritéria a poznámka pomohou rozhodnout, ale můžete je vynechat.
A11: Celkově: jak daleko má verze k vydání na VysokeSkoly.cz
A12: Úhel a zpracování: vybral článek z tématu to podstatné pro uchazeče a studenty a je to zajímavé?
A13: Fakta: sedí údaje se zdroji, nic není domyšlené ani zkreslené? Ověřená fakta jsou u každého článku v podkladu.
A14: Styl a tón: čtivost, srozumitelnost, tón VysokeSkoly.cz
... A31: Na dotazy odpoví Tomáš Hruška (tomas.hruska@effistream.eu).
